2025-09-01 15:44:57,168 - INFO - D:\data-hunter\crm_core\apiservice\crawler_dispatcher.py changed, reloading.
2025-09-01 15:48:25,350 - INFO - D:\data-hunter\crm_core\apiservice\crawler_dispatcher.py changed, reloading.
2025-09-01 15:48:28,536 - INFO - D:\data-hunter\crm_core\apiservice\crawler_dispatcher.py changed, reloading.
2025-09-01 16:00:06,958 - INFO - D:\data-hunter\crm_core\apiservice\crawler_dispatcher.py changed, reloading.
2025-09-01 16:00:29,029 - INFO - D:\data-hunter\crm_core\apiservice\crawler_dispatcher.py changed, reloading.
2025-09-01 16:00:33,360 - INFO - D:\data-hunter\crm_core\apiservice\crawler_dispatcher.py changed, reloading.
2025-09-01 16:00:46,842 - INFO - D:\data-hunter\crm_core\apiservice\crawler_dispatcher.py changed, reloading.
2025-09-01 16:00:50,316 - INFO - D:\data-hunter\crm_core\apiservice\crawler_dispatcher.py changed, reloading.
2025-09-01 16:01:04,716 - INFO - D:\data-hunter\crm_core\apiservice\crawler_dispatcher.py changed, reloading.
2025-09-01 16:01:12,101 - INFO - D:\data-hunter\crm_core\apiservice\crawler_dispatcher.py changed, reloading.
2025-09-01 16:01:19,995 - INFO - D:\data-hunter\crm_core\apiservice\crawler_dispatcher.py changed, reloading.
2025-09-01 16:01:29,409 - INFO - D:\data-hunter\crm_core\apiservice\crawler_dispatcher.py changed, reloading.
2025-09-01 16:03:32,526 - INFO - D:\data-hunter\crm_core\apiservice\crawler_dispatcher.py changed, reloading.
2025-09-01 16:03:59,901 - INFO - D:\data-hunter\crm_core\apiservice\crawler_dispatcher.py changed, reloading.
2025-09-01 16:04:03,166 - INFO - D:\data-hunter\crm_core\apiservice\crawler_dispatcher.py changed, reloading.
2025-09-01 16:07:47,507 - INFO - D:\data-hunter\crm_core\apiservice\crawler_dispatcher.py changed, reloading.
2025-09-01 16:08:40,035 - INFO - D:\data-hunter\crm_core\apiservice\task.py changed, reloading.
2025-09-01 16:11:33,810 - INFO - D:\data-hunter\crm_core\apiservice\views\hotel.py changed, reloading.
2025-09-01 16:12:10,703 - ERROR - Internal Server Error: /sendRequest/hotel/
Traceback (most recent call last):
  File "D:\data-hunter\venv\Lib\site-packages\django\core\handlers\exception.py", line 55, in inner
    response = get_response(request)
  File "D:\data-hunter\venv\Lib\site-packages\django\core\handlers\base.py", line 197, in _get_response
    response = wrapped_callback(request, *callback_args, **callback_kwargs)
  File "D:\data-hunter\venv\Lib\site-packages\django\views\decorators\csrf.py", line 65, in _view_wrapper
    return view_func(request, *args, **kwargs)
  File "D:\data-hunter\venv\Lib\site-packages\django\views\generic\base.py", line 105, in view
    return self.dispatch(request, *args, **kwargs)
           ~~~~~~~~~~~~~^^^^^^^^^^^^^^^^^^^^^^^^^^
  File "D:\data-hunter\venv\Lib\site-packages\rest_framework\views.py", line 515, in dispatch
    response = self.handle_exception(exc)
  File "D:\data-hunter\venv\Lib\site-packages\rest_framework\views.py", line 475, in handle_exception
    self.raise_uncaught_exception(exc)
    ~~~~~~~~~~~~~~~~~~~~~~~~~~~~~^^^^^
  File "D:\data-hunter\venv\Lib\site-packages\rest_framework\views.py", line 486, in raise_uncaught_exception
    raise exc
  File "D:\data-hunter\venv\Lib\site-packages\rest_framework\views.py", line 512, in dispatch
    response = handler(request, *args, **kwargs)
  File "D:\data-hunter\crm_core\apiservice\views\hotel.py", line 18, in post
    if serializer.is_valid():
       ~~~~~~~~~~~~~~~~~~~^^
  File "D:\data-hunter\venv\Lib\site-packages\rest_framework\serializers.py", line 225, in is_valid
    self._validated_data = self.run_validation(self.initial_data)
                           ~~~~~~~~~~~~~~~~~~~^^^^^^^^^^^^^^^^^^^
  File "D:\data-hunter\venv\Lib\site-packages\rest_framework\serializers.py", line 444, in run_validation
    value = self.to_internal_value(data)
  File "D:\data-hunter\venv\Lib\site-packages\rest_framework\serializers.py", line 503, in to_internal_value
    validated_value = validate_method(validated_value)
  File "D:\data-hunter\crm_core\apiservice\serializers\request.py", line 42, in validate_site_name
    all_site_names = CrawlerCache.get_cached_site_names()
TypeError: CrawlerCache.get_cached_site_names() missing 1 required positional argument: 'self'
2025-09-01 16:15:05,876 - INFO - D:\data-hunter\crm_core\apiservice\serializers\request.py changed, reloading.
2025-09-01 16:15:28,399 - ERROR - Internal Server Error: /sendRequest/hotel/
Traceback (most recent call last):
  File "D:\data-hunter\venv\Lib\site-packages\django\core\handlers\exception.py", line 55, in inner
    response = get_response(request)
  File "D:\data-hunter\venv\Lib\site-packages\django\core\handlers\base.py", line 197, in _get_response
    response = wrapped_callback(request, *callback_args, **callback_kwargs)
  File "D:\data-hunter\venv\Lib\site-packages\django\views\decorators\csrf.py", line 65, in _view_wrapper
    return view_func(request, *args, **kwargs)
  File "D:\data-hunter\venv\Lib\site-packages\django\views\generic\base.py", line 105, in view
    return self.dispatch(request, *args, **kwargs)
           ~~~~~~~~~~~~~^^^^^^^^^^^^^^^^^^^^^^^^^^
  File "D:\data-hunter\venv\Lib\site-packages\rest_framework\views.py", line 515, in dispatch
    response = self.handle_exception(exc)
  File "D:\data-hunter\venv\Lib\site-packages\rest_framework\views.py", line 475, in handle_exception
    self.raise_uncaught_exception(exc)
    ~~~~~~~~~~~~~~~~~~~~~~~~~~~~~^^^^^
  File "D:\data-hunter\venv\Lib\site-packages\rest_framework\views.py", line 486, in raise_uncaught_exception
    raise exc
  File "D:\data-hunter\venv\Lib\site-packages\rest_framework\views.py", line 512, in dispatch
    response = handler(request, *args, **kwargs)
  File "D:\data-hunter\crm_core\apiservice\views\hotel.py", line 18, in post
    if serializer.is_valid():
       ~~~~~~~~~~~~~~~~~~~^^
  File "D:\data-hunter\venv\Lib\site-packages\rest_framework\serializers.py", line 225, in is_valid
    self._validated_data = self.run_validation(self.initial_data)
                           ~~~~~~~~~~~~~~~~~~~^^^^^^^^^^^^^^^^^^^
  File "D:\data-hunter\venv\Lib\site-packages\rest_framework\serializers.py", line 444, in run_validation
    value = self.to_internal_value(data)
  File "D:\data-hunter\venv\Lib\site-packages\rest_framework\serializers.py", line 503, in to_internal_value
    validated_value = validate_method(validated_value)
  File "D:\data-hunter\crm_core\apiservice\serializers\request.py", line 42, in validate_site_name
    all_site_names = CrawlerCache(1).get_cached_site_names()
  File "D:\data-hunter\crm_core\crawler\crawler_cache.py", line 24, in get_cached_site_names
    cached = self.site_names_cache.get(self.SITE_NAMES_CACHE_KEY)
             ^^^^^^^^^^^^^^^^^^^^^^^^^
AttributeError: 'CrawlerRedisClient' object has no attribute 'get'
2025-09-01 16:25:14,650 - INFO - D:\data-hunter\crm_core\crm_core\redis\cache_processor.py changed, reloading.
2025-09-01 16:27:17,324 - INFO - D:\data-hunter\crm_core\crm_core\redis\cache_processor.py changed, reloading.
2025-09-01 16:27:50,512 - INFO - D:\data-hunter\crm_core\crawler\crawler_cache.py changed, reloading.
2025-09-01 16:27:53,936 - INFO - D:\data-hunter\crm_core\crawler\crawler_cache.py changed, reloading.
2025-09-01 16:27:56,553 - INFO - D:\data-hunter\crm_core\crawler\crawler_cache.py changed, reloading.
2025-09-01 16:28:04,241 - INFO - D:\data-hunter\crm_core\crawler\crawler_cache.py changed, reloading.
2025-09-01 16:28:11,666 - INFO - D:\data-hunter\crm_core\crawler\crawler_cache.py changed, reloading.
2025-09-01 16:28:15,324 - INFO - D:\data-hunter\crm_core\crawler\crawler_cache.py changed, reloading.
2025-09-01 16:28:21,977 - INFO - D:\data-hunter\crm_core\crawler\crawler_cache.py changed, reloading.
2025-09-01 16:29:37,850 - INFO - D:\data-hunter\crm_core\crawler\crawler_cache.py changed, reloading.
2025-09-01 16:30:33,612 - INFO - D:\data-hunter\crm_core\crm_core\redis\cache_processor.py changed, reloading.
2025-09-01 16:30:48,690 - INFO - D:\data-hunter\crm_core\crm_core\redis\cache_processor.py changed, reloading.
2025-09-01 16:30:59,313 - INFO - D:\data-hunter\crm_core\crawler\crawler_cache.py changed, reloading.
2025-09-01 16:48:43,627 - INFO - D:\data-hunter\crm_core\apiservice\crawler_dispatcher.py changed, reloading.
2025-09-01 16:54:04,630 - INFO - D:\data-hunter\crm_core\apiservice\task.py changed, reloading.
2025-09-01 17:00:14,694 - INFO - D:\data-hunter\crm_core\marriott\marriott\marriott_s.py changed, reloading.
2025-09-01 17:00:17,345 - INFO - D:\data-hunter\crm_core\marriott\marriott\marriott_s.py changed, reloading.
2025-09-01 17:00:21,981 - INFO - D:\data-hunter\crm_core\marriott\marriott\marriott_s.py changed, reloading.
2025-09-01 17:00:26,352 - INFO - D:\data-hunter\crm_core\marriott\marriott\marriott_s.py changed, reloading.
2025-09-01 17:00:31,810 - INFO - D:\data-hunter\crm_core\marriott\marriott\marriott_s.py changed, reloading.
2025-09-01 17:00:42,319 - INFO - D:\data-hunter\crm_core\marriott\marriott\marriott_s.py changed, reloading.
2025-09-01 17:00:44,708 - INFO - D:\data-hunter\crm_core\marriott\marriott\marriott_s.py changed, reloading.
2025-09-01 17:00:50,118 - INFO - D:\data-hunter\crm_core\marriott\marriott\marriott_s.py changed, reloading.
2025-09-01 17:01:02,715 - INFO - D:\data-hunter\crm_core\marriott\marriott\marriott_s.py changed, reloading.
2025-09-01 17:01:06,393 - INFO - D:\data-hunter\crm_core\marriott\marriott\marriott_s.py changed, reloading.
2025-09-01 17:01:08,945 - INFO - D:\data-hunter\crm_core\marriott\marriott\marriott_s.py changed, reloading.
2025-09-01 17:01:16,530 - INFO - D:\data-hunter\crm_core\marriott\marriott\marriott_s.py changed, reloading.
2025-09-01 17:01:20,059 - INFO - D:\data-hunter\crm_core\marriott\marriott\marriott_s.py changed, reloading.
2025-09-01 17:01:25,693 - INFO - D:\data-hunter\crm_core\marriott\marriott\marriott_s.py changed, reloading.
2025-09-01 17:01:29,120 - INFO - D:\data-hunter\crm_core\marriott\marriott\marriott_s.py changed, reloading.
2025-09-01 17:11:11,692 - INFO - D:\data-hunter\crm_core\apiservice\task.py changed, reloading.
2025-09-01 17:21:53,988 - INFO - D:\data-hunter\crm_core\marriott\marriott\marriott_s.py changed, reloading.
2025-09-01 17:22:03,647 - INFO - D:\data-hunter\crm_core\marriott\marriott\marriott_s.py changed, reloading.
2025-09-02 20:58:19,180 - WARNING - Not Found: /favicon.ico
2025-09-02 21:40:48,233 - INFO - D:\data-hunter\crm_core\apiservice\task.py changed, reloading.
2025-09-02 21:41:34,264 - INFO - D:\data-hunter\crm_core\apiservice\views\airline.py changed, reloading.
2025-09-02 21:42:17,519 - INFO - D:\data-hunter\crm_core\apiservice\views\airline.py changed, reloading.
2025-09-02 21:42:38,227 - INFO - D:\data-hunter\crm_core\apiservice\views\airline.py changed, reloading.
2025-09-02 21:43:06,903 - INFO - D:\data-hunter\crm_core\apiservice\task.py changed, reloading.
2025-09-03 11:58:58,915 - WARNING - Not Found: /favicon.ico
2025-09-03 12:08:33,140 - INFO - D:\data-hunter\crm_core\apiservice\serializers\request.py changed, reloading.
2025-09-03 12:30:42,305 - ERROR - Internal Server Error: /sendRequest/hotel/
Traceback (most recent call last):
  File "D:\data-hunter\venv\Lib\site-packages\django\db\backends\utils.py", line 105, in _execute
    return self.cursor.execute(sql, params)
           ~~~~~~~~~~~~~~~~~~~^^^^^^^^^^^^^
  File "D:\data-hunter\venv\Lib\site-packages\django\db\backends\sqlite3\base.py", line 360, in execute
    return super().execute(query, params)
           ~~~~~~~~~~~~~~~^^^^^^^^^^^^^^^
sqlite3.IntegrityError: NOT NULL constraint failed: apiservice_request.site_name

The above exception was the direct cause of the following exception:

Traceback (most recent call last):
  File "D:\data-hunter\venv\Lib\site-packages\django\core\handlers\exception.py", line 55, in inner
    response = get_response(request)
  File "D:\data-hunter\venv\Lib\site-packages\django\core\handlers\base.py", line 197, in _get_response
    response = wrapped_callback(request, *callback_args, **callback_kwargs)
  File "D:\data-hunter\venv\Lib\site-packages\django\views\decorators\csrf.py", line 65, in _view_wrapper
    return view_func(request, *args, **kwargs)
  File "D:\data-hunter\venv\Lib\site-packages\django\views\generic\base.py", line 105, in view
    return self.dispatch(request, *args, **kwargs)
           ~~~~~~~~~~~~~^^^^^^^^^^^^^^^^^^^^^^^^^^
  File "D:\data-hunter\venv\Lib\site-packages\rest_framework\views.py", line 515, in dispatch
    response = self.handle_exception(exc)
  File "D:\data-hunter\venv\Lib\site-packages\rest_framework\views.py", line 475, in handle_exception
    self.raise_uncaught_exception(exc)
    ~~~~~~~~~~~~~~~~~~~~~~~~~~~~~^^^^^
  File "D:\data-hunter\venv\Lib\site-packages\rest_framework\views.py", line 486, in raise_uncaught_exception
    raise exc
  File "D:\data-hunter\venv\Lib\site-packages\rest_framework\views.py", line 512, in dispatch
    response = handler(request, *args, **kwargs)
  File "D:\data-hunter\crm_core\apiservice\views\hotel.py", line 19, in post
    req = serializer.save()
  File "D:\data-hunter\venv\Lib\site-packages\rest_framework\serializers.py", line 210, in save
    self.instance = self.create(validated_data)
                    ~~~~~~~~~~~^^^^^^^^^^^^^^^^
  File "D:\data-hunter\venv\Lib\site-packages\rest_framework\serializers.py", line 991, in create
    instance = ModelClass._default_manager.create(**validated_data)
  File "D:\data-hunter\venv\Lib\site-packages\django\db\models\manager.py", line 87, in manager_method
    return getattr(self.get_queryset(), name)(*args, **kwargs)
           ~~~~~~~~~~~~~~~~~~~~~~~~~~~~~~~~~~^^^^^^^^^^^^^^^^^
  File "D:\data-hunter\venv\Lib\site-packages\django\db\models\query.py", line 663, in create
    obj.save(force_insert=True, using=self.db)
    ~~~~~~~~^^^^^^^^^^^^^^^^^^^^^^^^^^^^^^^^^^
  File "D:\data-hunter\venv\Lib\site-packages\django\db\models\base.py", line 902, in save
    self.save_base(
    ~~~~~~~~~~~~~~^
        using=using,
        ^^^^^^^^^^^^
    ...<2 lines>...
        update_fields=update_fields,
        ^^^^^^^^^^^^^^^^^^^^^^^^^^^^
    )
    ^
  File "D:\data-hunter\venv\Lib\site-packages\django\db\models\base.py", line 1008, in save_base
    updated = self._save_table(
        raw,
    ...<4 lines>...
        update_fields,
    )
  File "D:\data-hunter\venv\Lib\site-packages\django\db\models\base.py", line 1169, in _save_table
    results = self._do_insert(
        cls._base_manager, using, fields, returning_fields, raw
    )
  File "D:\data-hunter\venv\Lib\site-packages\django\db\models\base.py", line 1210, in _do_insert
    return manager._insert(
           ~~~~~~~~~~~~~~~^
        [self],
        ^^^^^^^
    ...<3 lines>...
        raw=raw,
        ^^^^^^^^
    )
    ^
  File "D:\data-hunter\venv\Lib\site-packages\django\db\models\manager.py", line 87, in manager_method
    return getattr(self.get_queryset(), name)(*args, **kwargs)
           ~~~~~~~~~~~~~~~~~~~~~~~~~~~~~~~~~~^^^^^^^^^^^^^^^^^
  File "D:\data-hunter\venv\Lib\site-packages\django\db\models\query.py", line 1868, in _insert
    return query.get_compiler(using=using).execute_sql(returning_fields)
           ~~~~~~~~~~~~~~~~~~~~~~~~~~~~~~~~~~~~~~~~~~~^^^^^^^^^^^^^^^^^^
  File "D:\data-hunter\venv\Lib\site-packages\django\db\models\sql\compiler.py", line 1882, in execute_sql
    cursor.execute(sql, params)
    ~~~~~~~~~~~~~~^^^^^^^^^^^^^
  File "D:\data-hunter\venv\Lib\site-packages\django\db\backends\utils.py", line 122, in execute
    return super().execute(sql, params)
           ~~~~~~~~~~~~~~~^^^^^^^^^^^^^
  File "D:\data-hunter\venv\Lib\site-packages\django\db\backends\utils.py", line 79, in execute
    return self._execute_with_wrappers(
           ~~~~~~~~~~~~~~~~~~~~~~~~~~~^
        sql, params, many=False, executor=self._execute
        ^^^^^^^^^^^^^^^^^^^^^^^^^^^^^^^^^^^^^^^^^^^^^^^
    )
    ^
  File "D:\data-hunter\venv\Lib\site-packages\django\db\backends\utils.py", line 92, in _execute_with_wrappers
    return executor(sql, params, many, context)
  File "D:\data-hunter\venv\Lib\site-packages\django\db\backends\utils.py", line 100, in _execute
    with self.db.wrap_database_errors:
         ^^^^^^^^^^^^^^^^^^^^^^^^^^^^
  File "D:\data-hunter\venv\Lib\site-packages\django\db\utils.py", line 91, in __exit__
    raise dj_exc_value.with_traceback(traceback) from exc_value
  File "D:\data-hunter\venv\Lib\site-packages\django\db\backends\utils.py", line 105, in _execute
    return self.cursor.execute(sql, params)
           ~~~~~~~~~~~~~~~~~~~^^^^^^^^^^^^^
  File "D:\data-hunter\venv\Lib\site-packages\django\db\backends\sqlite3\base.py", line 360, in execute
    return super().execute(query, params)
           ~~~~~~~~~~~~~~~^^^^^^^^^^^^^^^
django.db.utils.IntegrityError: NOT NULL constraint failed: apiservice_request.site_name
2025-09-03 12:32:56,897 - ERROR - Internal Server Error: /sendRequest/hotel/
Traceback (most recent call last):
  File "D:\data-hunter\venv\Lib\site-packages\django\db\backends\utils.py", line 105, in _execute
    return self.cursor.execute(sql, params)
           ~~~~~~~~~~~~~~~~~~~^^^^^^^^^^^^^
  File "D:\data-hunter\venv\Lib\site-packages\django\db\backends\sqlite3\base.py", line 360, in execute
    return super().execute(query, params)
           ~~~~~~~~~~~~~~~^^^^^^^^^^^^^^^
sqlite3.IntegrityError: NOT NULL constraint failed: apiservice_request.site_name

The above exception was the direct cause of the following exception:

Traceback (most recent call last):
  File "D:\data-hunter\venv\Lib\site-packages\django\core\handlers\exception.py", line 55, in inner
    response = get_response(request)
  File "D:\data-hunter\venv\Lib\site-packages\django\core\handlers\base.py", line 197, in _get_response
    response = wrapped_callback(request, *callback_args, **callback_kwargs)
  File "D:\data-hunter\venv\Lib\site-packages\django\views\decorators\csrf.py", line 65, in _view_wrapper
    return view_func(request, *args, **kwargs)
  File "D:\data-hunter\venv\Lib\site-packages\django\views\generic\base.py", line 105, in view
    return self.dispatch(request, *args, **kwargs)
           ~~~~~~~~~~~~~^^^^^^^^^^^^^^^^^^^^^^^^^^
  File "D:\data-hunter\venv\Lib\site-packages\rest_framework\views.py", line 515, in dispatch
    response = self.handle_exception(exc)
  File "D:\data-hunter\venv\Lib\site-packages\rest_framework\views.py", line 475, in handle_exception
    self.raise_uncaught_exception(exc)
    ~~~~~~~~~~~~~~~~~~~~~~~~~~~~~^^^^^
  File "D:\data-hunter\venv\Lib\site-packages\rest_framework\views.py", line 486, in raise_uncaught_exception
    raise exc
  File "D:\data-hunter\venv\Lib\site-packages\rest_framework\views.py", line 512, in dispatch
    response = handler(request, *args, **kwargs)
  File "D:\data-hunter\crm_core\apiservice\views\hotel.py", line 19, in post
    req = serializer.save()
  File "D:\data-hunter\venv\Lib\site-packages\rest_framework\serializers.py", line 210, in save
    self.instance = self.create(validated_data)
                    ~~~~~~~~~~~^^^^^^^^^^^^^^^^
  File "D:\data-hunter\venv\Lib\site-packages\rest_framework\serializers.py", line 991, in create
    instance = ModelClass._default_manager.create(**validated_data)
  File "D:\data-hunter\venv\Lib\site-packages\django\db\models\manager.py", line 87, in manager_method
    return getattr(self.get_queryset(), name)(*args, **kwargs)
           ~~~~~~~~~~~~~~~~~~~~~~~~~~~~~~~~~~^^^^^^^^^^^^^^^^^
  File "D:\data-hunter\venv\Lib\site-packages\django\db\models\query.py", line 663, in create
    obj.save(force_insert=True, using=self.db)
    ~~~~~~~~^^^^^^^^^^^^^^^^^^^^^^^^^^^^^^^^^^
  File "D:\data-hunter\venv\Lib\site-packages\django\db\models\base.py", line 902, in save
    self.save_base(
    ~~~~~~~~~~~~~~^
        using=using,
        ^^^^^^^^^^^^
    ...<2 lines>...
        update_fields=update_fields,
        ^^^^^^^^^^^^^^^^^^^^^^^^^^^^
    )
    ^
  File "D:\data-hunter\venv\Lib\site-packages\django\db\models\base.py", line 1008, in save_base
    updated = self._save_table(
        raw,
    ...<4 lines>...
        update_fields,
    )
  File "D:\data-hunter\venv\Lib\site-packages\django\db\models\base.py", line 1169, in _save_table
    results = self._do_insert(
        cls._base_manager, using, fields, returning_fields, raw
    )
  File "D:\data-hunter\venv\Lib\site-packages\django\db\models\base.py", line 1210, in _do_insert
    return manager._insert(
           ~~~~~~~~~~~~~~~^
        [self],
        ^^^^^^^
    ...<3 lines>...
        raw=raw,
        ^^^^^^^^
    )
    ^
  File "D:\data-hunter\venv\Lib\site-packages\django\db\models\manager.py", line 87, in manager_method
    return getattr(self.get_queryset(), name)(*args, **kwargs)
           ~~~~~~~~~~~~~~~~~~~~~~~~~~~~~~~~~~^^^^^^^^^^^^^^^^^
  File "D:\data-hunter\venv\Lib\site-packages\django\db\models\query.py", line 1868, in _insert
    return query.get_compiler(using=using).execute_sql(returning_fields)
           ~~~~~~~~~~~~~~~~~~~~~~~~~~~~~~~~~~~~~~~~~~~^^^^^^^^^^^^^^^^^^
  File "D:\data-hunter\venv\Lib\site-packages\django\db\models\sql\compiler.py", line 1882, in execute_sql
    cursor.execute(sql, params)
    ~~~~~~~~~~~~~~^^^^^^^^^^^^^
  File "D:\data-hunter\venv\Lib\site-packages\django\db\backends\utils.py", line 122, in execute
    return super().execute(sql, params)
           ~~~~~~~~~~~~~~~^^^^^^^^^^^^^
  File "D:\data-hunter\venv\Lib\site-packages\django\db\backends\utils.py", line 79, in execute
    return self._execute_with_wrappers(
           ~~~~~~~~~~~~~~~~~~~~~~~~~~~^
        sql, params, many=False, executor=self._execute
        ^^^^^^^^^^^^^^^^^^^^^^^^^^^^^^^^^^^^^^^^^^^^^^^
    )
    ^
  File "D:\data-hunter\venv\Lib\site-packages\django\db\backends\utils.py", line 92, in _execute_with_wrappers
    return executor(sql, params, many, context)
  File "D:\data-hunter\venv\Lib\site-packages\django\db\backends\utils.py", line 100, in _execute
    with self.db.wrap_database_errors:
         ^^^^^^^^^^^^^^^^^^^^^^^^^^^^
  File "D:\data-hunter\venv\Lib\site-packages\django\db\utils.py", line 91, in __exit__
    raise dj_exc_value.with_traceback(traceback) from exc_value
  File "D:\data-hunter\venv\Lib\site-packages\django\db\backends\utils.py", line 105, in _execute
    return self.cursor.execute(sql, params)
           ~~~~~~~~~~~~~~~~~~~^^^^^^^^^^^^^
  File "D:\data-hunter\venv\Lib\site-packages\django\db\backends\sqlite3\base.py", line 360, in execute
    return super().execute(query, params)
           ~~~~~~~~~~~~~~~^^^^^^^^^^^^^^^
django.db.utils.IntegrityError: NOT NULL constraint failed: apiservice_request.site_name
2025-09-03 12:38:18,170 - INFO - D:\data-hunter\crm_core\apiservice\serializers\request.py changed, reloading.
2025-09-03 12:44:55,189 - INFO - D:\data-hunter\crm_core\apiservice\serializers\request.py changed, reloading.
2025-09-03 12:49:49,292 - WARNING - Bad Request: /sendRequest/hotel/
